Processing folder: /mounts/data/proj/molly/LLM_bias_analysis/data/nemotron-3-8b-chat-4k-rlhf/
Traceback (most recent call last):
  File "/mounts/Users/cisintern/molly/miniconda3/envs/media_bias/lib/python3.10/site-packages/huggingface_hub/utils/_http.py", line 406, in hf_raise_for_status
    response.raise_for_status()
  File "/mounts/Users/cisintern/molly/miniconda3/envs/media_bias/lib/python3.10/site-packages/requests/models.py", line 1024, in raise_for_status
    raise HTTPError(http_error_msg, response=self)
requests.exceptions.HTTPError: 403 Client Error: Forbidden for url: https://huggingface.co/nvidia/nemotron-3-8b-chat-4k-rlhf/resolve/main/config.json

The above exception was the direct cause of the following exception:

Traceback (most recent call last):
  File "/mounts/Users/cisintern/molly/miniconda3/envs/media_bias/lib/python3.10/site-packages/transformers/utils/hub.py", line 403, in cached_file
    resolved_file = hf_hub_download(
  File "/mounts/Users/cisintern/molly/miniconda3/envs/media_bias/lib/python3.10/site-packages/huggingface_hub/utils/_validators.py", line 114, in _inner_fn
    return fn(*args, **kwargs)
  File "/mounts/Users/cisintern/molly/miniconda3/envs/media_bias/lib/python3.10/site-packages/huggingface_hub/file_download.py", line 862, in hf_hub_download
    return _hf_hub_download_to_cache_dir(
  File "/mounts/Users/cisintern/molly/miniconda3/envs/media_bias/lib/python3.10/site-packages/huggingface_hub/file_download.py", line 969, in _hf_hub_download_to_cache_dir
    _raise_on_head_call_error(head_call_error, force_download, local_files_only)
  File "/mounts/Users/cisintern/molly/miniconda3/envs/media_bias/lib/python3.10/site-packages/huggingface_hub/file_download.py", line 1484, in _raise_on_head_call_error
    raise head_call_error
  File "/mounts/Users/cisintern/molly/miniconda3/envs/media_bias/lib/python3.10/site-packages/huggingface_hub/file_download.py", line 1376, in _get_metadata_or_catch_error
    metadata = get_hf_file_metadata(
  File "/mounts/Users/cisintern/molly/miniconda3/envs/media_bias/lib/python3.10/site-packages/huggingface_hub/utils/_validators.py", line 114, in _inner_fn
    return fn(*args, **kwargs)
  File "/mounts/Users/cisintern/molly/miniconda3/envs/media_bias/lib/python3.10/site-packages/huggingface_hub/file_download.py", line 1296, in get_hf_file_metadata
    r = _request_wrapper(
  File "/mounts/Users/cisintern/molly/miniconda3/envs/media_bias/lib/python3.10/site-packages/huggingface_hub/file_download.py", line 277, in _request_wrapper
    response = _request_wrapper(
  File "/mounts/Users/cisintern/molly/miniconda3/envs/media_bias/lib/python3.10/site-packages/huggingface_hub/file_download.py", line 301, in _request_wrapper
    hf_raise_for_status(response)
  File "/mounts/Users/cisintern/molly/miniconda3/envs/media_bias/lib/python3.10/site-packages/huggingface_hub/utils/_http.py", line 423, in hf_raise_for_status
    raise _format(GatedRepoError, message, response) from e
huggingface_hub.errors.GatedRepoError: 403 Client Error. (Request ID: Root=1-679e566c-72496f0c7330752e3e832e35;1e7c54d9-35b7-4792-a36f-17a30ced2ec8)

Cannot access gated repo for url https://huggingface.co/nvidia/nemotron-3-8b-chat-4k-rlhf/resolve/main/config.json.
Your request to access model nvidia/nemotron-3-8b-chat-4k-rlhf is awaiting a review from the repo authors.

The above exception was the direct cause of the following exception:

Traceback (most recent call last):
  File "/nfs/datb/molly/LLM_bias_analysis/LLM_article_generation_functions/generate_articles.py", line 361, in <module>
    main()
  File "/nfs/datb/molly/LLM_bias_analysis/LLM_article_generation_functions/generate_articles.py", line 352, in main
    c4ai_output_single_file(
  File "/nfs/datb/molly/LLM_bias_analysis/LLM_article_generation_functions/generate_articles.py", line 241, in c4ai_output_single_file
    tokenizer = AutoTokenizer.from_pretrained(model_name, token=hf_token)
  File "/mounts/Users/cisintern/molly/miniconda3/envs/media_bias/lib/python3.10/site-packages/transformers/models/auto/tokenization_auto.py", line 891, in from_pretrained
    config = AutoConfig.from_pretrained(
  File "/mounts/Users/cisintern/molly/miniconda3/envs/media_bias/lib/python3.10/site-packages/transformers/models/auto/configuration_auto.py", line 1054, in from_pretrained
    config_dict, unused_kwargs = PretrainedConfig.get_config_dict(pretrained_model_name_or_path, **kwargs)
  File "/mounts/Users/cisintern/molly/miniconda3/envs/media_bias/lib/python3.10/site-packages/transformers/configuration_utils.py", line 591, in get_config_dict
    config_dict, kwargs = cls._get_config_dict(pretrained_model_name_or_path, **kwargs)
  File "/mounts/Users/cisintern/molly/miniconda3/envs/media_bias/lib/python3.10/site-packages/transformers/configuration_utils.py", line 650, in _get_config_dict
    resolved_config_file = cached_file(
  File "/mounts/Users/cisintern/molly/miniconda3/envs/media_bias/lib/python3.10/site-packages/transformers/utils/hub.py", line 421, in cached_file
    raise EnvironmentError(
OSError: You are trying to access a gated repo.
Make sure to have access to it at https://huggingface.co/nvidia/nemotron-3-8b-chat-4k-rlhf.
403 Client Error. (Request ID: Root=1-679e566c-72496f0c7330752e3e832e35;1e7c54d9-35b7-4792-a36f-17a30ced2ec8)

Cannot access gated repo for url https://huggingface.co/nvidia/nemotron-3-8b-chat-4k-rlhf/resolve/main/config.json.
Your request to access model nvidia/nemotron-3-8b-chat-4k-rlhf is awaiting a review from the repo authors.
